Workbook
Name product_category: products!$A$1:$B$13
Name countries: countries!$A$2:$E$250

Sheet dashboard

Sheet countries
A1: alpha-3 | B1: name | C1: alpha-2 | D1: region | E1: sub-region
A2: AFG | B2: Afghanistan | C2: AF | D2: Asia | E2: Southern Asia
A3: ALA | B3: Åland Islands | C3: AX | D3: Europe | E3: Northern Europe
A4: ALB | B4: Albania | C4: AL | D4: Europe | E4: Southern Europe
A5: DZA | B5: Algeria | C5: DZ | D5: Africa | E5: Northern Africa
A6: ASM | B6: American Samoa | C6: AS | D6: Oceania | E6: Polynesia
A7: AND | B7: Andorra | C7: AD | D7: Europe | E7: Southern Europe
A8: AGO | B8: Angola | C8: AO | D8: Africa | E8: Sub-Saharan Africa
A9: AIA | B9: Anguilla | C9: AI | D9: Americas | E9: Latin America and the Caribbean
A10: ATA | B10: Antarctica | C10: AQ | D10: Antarctica | E10: Antarctica
A11: ATG | B11: Antigua and Barbuda | C11: AG | D11: Americas | E11: Latin America and the Caribbean
A12: ARG | B12: Argentina | C12: AR | D12: Americas | E12: Latin America and the Caribbean
... A250: ZWE | B250: Zimbabwe | C250: ZW | D250: Africa | E250: Sub-Saharan Africa

Sheet events
A1: Product ID | B1: product category | C1: Order ID | D1: Order Date | E1: month number | F1: month of order | G1: day of order | H1: year of order | I1: Ship Date | J1: time of shipment | K1: Order Priority | L1: Country Code | M1: country | N1: region | O1: subregion | P1: Sales Channel | Q1: Units Sold | R1: Unit Price | S1: Unit Cost | T1: total revenue | U1: total cost | V1: total profit | W1: share of units sold | X1: cumulative share of units sold | Y1: share of revenue | Z1: cumulative share of revenue | AA1: share of total profit | AB1: cumulative share of total profit
A2: 2103 | B2: =VLOOKUP($A2,product_category,2, False) -> Cereal | C2: 100640618 | D2: 41920 | E2: =month(D2) -> 10 | F2: =text(D2,"MMM") -> Oct | G2: =Day(D2) -> 8 | H2: =year(D2) -> 2014 | I2: 41930 | J2: =DATEDIF(D2,I2,"D") -> 10 | K2: M | L2: NOR | M2: =VLOOKUP(L2,countries, 2,false) -> Norway | N2: =VLOOKUP(L2,countries, 4,false) -> Europe | O2: =VLOOKUP(L2,countries, 5,false) -> Northern Europe | P2: Online | Q2: 650 | R2: 205.7 | S2: 117.11 | T2: =MULTIPLY(Q2,R2) -> 133705 | U2: =MULTIPLY(Q3,S3) -> 233400.23 | V2: =MINUS(T2,U2) -> -99695.23 | W2: =Q2/totals!B$2 -> 9.8836407e-05 | X2: =W2 -> 9.8836407e-05 | Y2: =T2/totals!B$5 -> 7.8551607e-05 | Z2: =Y2 -> 7.8551607e-05 | AA2: =V2/totals!B$4 -> -0.00019878988 | AB2: =AA2 -> -0.00019878988
A3: 2103 | B3: =VLOOKUP($A3,product_category,2, False) -> Cereal | C3: 100983083 | D3: 42593 | E3: =month(D3) -> 8 | F3: =text(D3,"MMM") -> Aug | G3: =Day(D3) -> 11 | H3: =year(D3) -> 2016 | I3: 42593 | J3: =DATEDIF(D3,I3,"D") -> 0 | K3: C | L3: SRB | M3: =VLOOKUP(L3,countries, 2,false) -> Serbia | N3: =VLOOKUP(L3,countries, 4,false) -> Europe | O3: =VLOOKUP(L3,countries, 5,false) -> Southern Europe | P3: Offline | Q3: 1993 | R3: 205.7 | S3: 117.11 | T3: =MULTIPLY(Q3,R3) -> 409960.1 | U3: =MULTIPLY(Q4,S4) -> 2358420.2 | V3: =MINUS(T3,U3) -> -1948460.1 | W3: =Q3/totals!B$2 -> 0.00030304763 | X3: =W3+X2 -> 0.00040188403 | Y3: =T3/totals!B$5 -> 0.00024085131 | Z3: =Z2+Y3 -> 0.00031940292 | AA3: =V3/totals!B$4 -> -0.0038851825 | AB3: =AB2+AA3 -> -0.0040839724
A4: 7940 | B4: =VLOOKUP($A4,product_category,2, False) -> Household | C4: 101025998 | D4: 41838 | E4: =month(D4) -> 7 | F4: =text(D4,"MMM") -> Jul | G4: =Day(D4) -> 18 | H4: =year(D4) -> 2014 | I4: 41862 | J4: =DATEDIF(D4,I4,"D") -> 24 | K4: M | L4: #N/A | P4: Online | Q4: 4693 | R4: 668.27 | S4: 502.54 | T4: =MULTIPLY(Q4,R4) -> 3136191.1 | U4: =MULTIPLY(Q5,S5) -> 41968.64 | V4: =MINUS(T4,U4) -> 3094222.5 | W4: =Q4/totals!B$2 -> 0.00071359886 | X4: =W4+X3 -> 0.0011154829 | Y4: =T4/totals!B$5 -> 0.0018425104 | Z4: =Z3+Y4 -> 0.0021619133 | AA4: =V4/totals!B$4 -> 0.006169805 | AB4: =AB3+AA4 -> 0.0020858326
A5: 2455 | B5: =VLOOKUP($A5,product_category,2, False) -> Clothes | C5: 102230632 | D5: 42868 | E5: =month(D5) -> 5 | F5: =text(D5,"MMM") -> May | G5: =Day(D5) -> 13 | H5: =year(D5) -> 2017 | I5: 42899 | J5: =DATEDIF(D5,I5,"D") -> 31 | K5: L | L5: MNE | M5: =VLOOKUP(L5,countries, 2,false) -> Montenegro | N5: =VLOOKUP(L5,countries, 4,false) -> Europe | O5: =VLOOKUP(L5,countries, 5,false) -> Southern Europe | P5: Online | Q5: 1171 | R5: 109.28 | S5: 35.84 | T5: =MULTIPLY(Q5,R5) -> 127966.88 | U5: =MULTIPLY(Q6,S6) -> 243129.92 | V5: =MINUS(T5,U5) -> -115163.04 | W5: =Q5/totals!B$2 -> 0.00017805759 | X5: =W5+X4 -> 0.0012935405 | Y5: =T5/totals!B$5 -> 7.5180465e-05 | Z5: =Z4+Y5 -> 0.0022370938 | AA5: =V5/totals!B$4 -> -0.00022963232 | AB5: =AB4+AA5 -> 0.0018562003
A6: 1270 | B6: =VLOOKUP($A6,product_category,2, False) -> Beverages | C6: 103435266 | D6: 41132 | E6: =month(D6) -> 8 | F6: =text(D6,"MMM") -> Aug | G6: =Day(D6) -> 11 | H6: =year(D6) -> 2012 | I6: 41170 | J6: =DATEDIF(D6,I6,"D") -> 38 | K6: H | L6: SRB | M6: =VLOOKUP(L6,countries, 2,false) -> Serbia | N6: =VLOOKUP(L6,countries, 4,false) -> Europe | O6: =VLOOKUP(L6,countries, 5,false) -> Southern Europe | P6: Offline | Q6: 7648 | R6: 47.45 | S6: 31.79 | T6: =MULTIPLY(Q6,R6) -> 362897.6 | U6: =MULTIPLY(Q7,S7) -> 1165411.2 | V6: =MINUS(T6,U6) -> -802513.6 | W6: =Q6/totals!B$2 -> 0.0011629244 | X6: =W6+X5 -> 0.0024564648 | Y6: =T6/totals!B$5 -> 0.00021320212 | Z6: =Z5+Y6 -> 0.0024502959 | AA6: =V6/totals!B$4 -> -0.0016001928 | AB6: =AB5+AA6 -> 0.00025600752
A7: 8681 | B7: =VLOOKUP($A7,product_category,2, False) -> Office Supplies | C7: 103450715 | D7: 42078 | E7: =month(D7) -> 3 | F7: =text(D7,"MMM") -> Mar | G7: =Day(D7) -> 15 | H7: =year(D7) -> 2015 | I7: 42112 | J7: =DATEDIF(D7,I7,"D") -> 34 | K7: H | L7: SVK | M7: =VLOOKUP(L7,countries, 2,false) -> Slovakia | N7: =VLOOKUP(L7,countries, 4,false) -> Europe | O7: =VLOOKUP(L7,countries, 5,false) -> Eastern Europe | P7: Online | Q7: 2220 | R7: 651.21 | S7: 524.96 | T7: =MULTIPLY(Q7,R7) -> 1445686.2 | U7: =MULTIPLY(Q8,S8) -> 46350.16 | V7: =MINUS(T7,U7) -> 1399336 | W7: =Q7/totals!B$2 -> 0.00033756434 | X7: =W7+X6 -> 0.0027940292 | Y7: =T7/totals!B$5 -> 0.00084933977 | Z7: =Z6+Y7 -> 0.0032996357 | AA7: =V7/totals!B$4 -> 0.0027902423 | AB7: =AB6+AA7 -> 0.0030462498
A8: 4594 | B8: =VLOOKUP($A8,product_category,2, False) -> Fruits | C8: 103499639 | D8: 41384 | E8: =month(D8) -> 4 | F8: =text(D8,"MMM") -> Apr | G8: =Day(D8) -> 20 | H8: =year(D8) -> 2013 | I8: 41431 | J8: =DATEDIF(D8,I8,"D") -> 47 | K8: L | L8: FRA | M8: =VLOOKUP(L8,countries, 2,false) -> France | N8: =VLOOKUP(L8,countries, 4,false) -> Europe | O8: =VLOOKUP(L8,countries, 5,false) -> Western Europe | P8: Online | Q8: 6698 | R8: 9.33 | S8: 6.92 | T8: =MULTIPLY(Q8,R8) -> 62492.34 | U8: =MULTIPLY(Q9,S9) -> 401819.67 | V8: =MINUS(T8,U8) -> -339327.33 | W8: =Q8/totals!B$2 -> 0.0010184712 | X8: =W8+X7 -> 0.0038125003 | Y8: =T8/totals!B$5 -> 3.6714212e-05 | Z8: =Z7+Y8 -> 0.0033363499 | AA8: =V8/totals!B$4 -> -0.00067661051 | AB8: =AB7+AA8 -> 0.0023696393
A9: 5988 | B9: =VLOOKUP($A9,product_category,2, False) -> Vegetables | C9: 103762280 | D9: 40859 | E9: =month(D9) -> 11 | F9: =text(D9,"MMM") -> Nov | G9: =Day(D9) -> 12 | H9: =year(D9) -> 2011 | I9: 40891 | J9: =DATEDIF(D9,I9,"D") -> 32 | K9: M | L9: ESP | M9: =VLOOKUP(L9,countries, 2,false) -> Spain | N9: =VLOOKUP(L9,countries, 4,false) -> Europe | O9: =VLOOKUP(L9,countries, 5,false) -> Southern Europe | P9: Online | Q9: 4419 | R9: 154.06 | S9: 90.93 | T9: =MULTIPLY(Q9,R9) -> 680791.14 | U9: =MULTIPLY(Q10,S10) -> 836476.74 | V9: =MINUS(T9,U9) -> -155685.6 | W9: =Q9/totals!B$2 -> 0.00067193551 | X9: =W9+X8 -> 0.0044844359 | Y9: =T9/totals!B$5 -> 0.00039996438 | Z9: =Z8+Y9 -> 0.0037363143 | AA9: =V9/totals!B$4 -> -0.00031043333 | AB9: =AB8+AA9 -> 0.002059206
A10: 7331 | B10: =VLOOKUP($A10,product_category,2, False) -> Baby Food | C10: 103832662 | D10: 41171 | E10: =month(D10) -> 9 | F10: =text(D10,"MMM") -> Sep | G10: =Day(D10) -> 19 | H10: =year(D10) -> 2012 | I10: 41202 | J10: =DATEDIF(D10,I10,"D") -> 31 | K10: H | L10: HRV | M10: =VLOOKUP(L10,countries, 2,false) -> Croatia | N10: =VLOOKUP(L10,countries, 4,false) -> Europe | O10: =VLOOKUP(L10,countries, 5,false) -> Southern Europe | P10: Offline | Q10: 5247 | R10: 255.28 | S10: 159.42 | T10: =MULTIPLY(Q10,R10) -> 1339454.2 | U10: =MULTIPLY(Q11,S11) -> 856659.65 | V10: =MINUS(T10,U10) -> 482794.51 | W10: =Q10/totals!B$2 -> 0.00079783789 | X10: =W10+X9 -> 0.0052822737 | Y10: =T10/totals!B$5 -> 0.00078692851 | Z10: =Z9+Y10 -> 0.0045232428 | AA10: =V10/totals!B$4 -> 0.00096268061 | AB10: =AB9+AA10 -> 0.0030218866
A11: 2103 | B11: =VLOOKUP($A11,product_category,2, False) -> Cereal | C11: 104008615 | D11: 40566 | E11: =month(D11) -> 1 | F11: =text(D11,"MMM") -> Jan | G11: =Day(D11) -> 23 | H11: =year(D11) -> 2011 | I11: 40596 | J11: =DATEDIF(D11,I11,"D") -> 30 | K11: M | L11: DEU | M11: =VLOOKUP(L11,countries, 2,false) -> Germany | N11: =VLOOKUP(L11,countries, 4,false) -> Europe | O11: =VLOOKUP(L11,countries, 5,false) -> Western Europe | P11: Online | Q11: 7315 | R11: 205.7 | S11: 117.11 | T11: =MULTIPLY(Q11,R11) -> 1504695.5 | U11: =MULTIPLY(Q12,S12) -> 1907641.8 | V11: =MINUS(T11,U11) -> -402946.34 | W11: =Q11/totals!B$2 -> 0.0011122897 | X11: =W11+X10 -> 0.0063945634 | Y11: =T11/totals!B$5 -> 0.0008840077 | Z11: =Z10+Y11 -> 0.0054072505 | AA11: =V11/totals!B$4 -> -0.00080346528 | AB11: =AB10+AA11 -> 0.0022184213
A12: 7940 | B12: =VLOOKUP($A12,product_category,2, False) -> Household | C12: 104165685 | D12: 40958 | E12: =month(D12) -> 2 | F12: =text(D12,"MMM") -> Feb | G12: =Day(D12) -> 19 | H12: =year(D12) -> 2012 | I12: 40974 | J12: =DATEDIF(D12,I12,"D") -> 16 | K12: L | L12: ARM | M12: =VLOOKUP(L12,countries, 2,false) -> Armenia | N12: =VLOOKUP(L12,countries, 4,false) -> Asia | O12: =VLOOKUP(L12,countries, 5,false) -> Western Asia | P12: Online | Q12: 3796 | R12: 668.27 | S12: 502.54 | T12: =MULTIPLY(Q12,R12) -> 2536752.9 | U12: =MULTIPLY(Q13,S13) -> 423769.78 | V12: =MINUS(T12,U12) -> 2112983.1 | W12: =Q12/totals!B$2 -> 0.00057720461 | X12: =W12+X11 -> 0.0069717681 | Y12: =T12/totals!B$5 -> 0.0014903408 | Z12: =Z11+Y12 -> 0.0068975913 | AA12: =V12/totals!B$4 -> 0.0042132374 | AB12: =AB11+AA12 -> 0.0064316587
A13: 8875 | B13: =VLOOKUP($A13,product_category,2, False) -> Meat | C13: 104190576 | D13: 42788 | E13: =month(D13) -> 2 | F13: =text(D13,"MMM") -> Feb | G13: =Day(D13) -> 22 | H13: =year(D13) -> 2017 | I13: 42806 | J13: =DATEDIF(D13,I13,"D") -> 18 | K13: C | L13: GEO | M13: =VLOOKUP(L13,countries, 2,false) -> Georgia | N13: =VLOOKUP(L13,countries, 4,false) -> Asia | O13: =VLOOKUP(L13,countries, 5,false) -> Western Asia | P13: Offline | Q13: 1162 | R13: 421.89 | S13: 364.69 | T13: =MULTIPLY(Q13,R13) -> 490236.18 | U13: =MULTIPLY(Q14,S14) -> 50446.8 | V13: =MINUS(T13,U13) -> 439789.38 | W13: =Q13/totals!B$2 -> 0.00017668908 | X13: =W13+X12 -> 0.0071484571 | Y13: =T13/totals!B$5 -> 0.00028801346 | Z13: =Z12+Y13 -> 0.0071856047 | AA13: =V13/totals!B$4 -> 0.00087692942 | AB13: =AB12+AA13 -> 0.0073085881
A14: 4594 | B14: =VLOOKUP($A14,product_category,2, False) -> Fruits | C14: 104245078 | D14: 41360 | E14: =month(D14) -> 3 | F14: =text(D14,"MMM") -> Mar | G14: =Day(D14) -> 27 | H14: =year(D14) -> 2013 | I14: 41385 | J14: =DATEDIF(D14,I14,"D") -> 25 | K14: M | L14: GBR | M14: =VLOOKUP(L14,countries, 2,false) -> United Kingdom | N14: =VLOOKUP(L14,countries, 4,false) -> Europe | O14: =VLOOKUP(L14,countries, 5,false) -> Northern Europe | P14: Offline | Q14: 7290 | R14: 9.33 | S14: 6.92 | T14: =MULTIPLY(Q14,R14) -> 68015.7 | U14: =MULTIPLY(Q15,S15) -> 1128055.9 | V14: =MINUS(T14,U14) -> -1060040.2 | W14: =Q14/totals!B$2 -> 0.0011084883 | X14: =W14+X13 -> 0.0082569455 | Y14: =T14/totals!B$5 -> 3.9959183e-05 | Z14: =Z13+Y14 -> 0.0072255639 | AA14: =V14/totals!B$4 -> -0.0021136946 | AB14: =AB13+AA14 -> 0.0051948935
A15: 7331 | B15: =VLOOKUP($A15,product_category,2, False) -> Baby Food | C15: 104548490 | D15: 41640 | E15: =month(D15) -> 1 | F15: =text(D15,"MMM") -> Jan | G15: =Day(D15) -> 1 | H15: =year(D15) -> 2014 | I15: 41644 | J15: =DATEDIF(D15,I15,"D") -> 4 | K15: M | L15: #N/A | P15: Online | Q15: 7076 | R15: 255.28 | S15: 159.42 | T15: =MULTIPLY(Q15,R15) -> 1806361.3 | U15: =MULTIPLY(Q16,S16) -> 342845.44 | V15: =MINUS(T15,U15) -> 1463515.8 | W15: =Q15/totals!B$2 -> 0.0010759483 | X15: =W15+X14 -> 0.0093328938 | Y15: =T15/totals!B$5 -> 0.0010612362 | Z15: =Z14+Y15 -> 0.0082868001 | AA15: =V15/totals!B$4 -> 0.0029182153 | AB15: =AB14+AA15 -> 0.0081131088
A16: 2455 | B16: =VLOOKUP($A16,product_category,2, False) -> Clothes | C16: 105030000 | D16: 42523 | E16: =month(D16) -> 6 | F16: =text(D16,"MMM") -> Jun | G16: =Day(D16) -> 2 | H16: =year(D16) -> 2016 | I16: 42534 | J16: =DATEDIF(D16,I16,"D") -> 11 | K16: C | L16: SVN | M16: =VLOOKUP(L16,countries, 2,false) -> Slovenia | N16: =VLOOKUP(L16,countries, 4,false) -> Europe | O16: =VLOOKUP(L16,countries, 5,false) -> Southern Europe | P16: Offline | Q16: 9566 | R16: 109.28 | S16: 35.84 | T16: =MULTIPLY(Q16,R16) -> 1045372.5 | U16: =MULTIPLY(Q17,S17) -> 2642355.3 | V16: =MINUS(T16,U16) -> -1596982.8 | W16: =Q16/totals!B$2 -> 0.0014545678 | X16: =W16+X15 -> 0.010787462 | Y16: =T16/totals!B$5 -> 0.0006141557 | Z16: =Z15+Y16 -> 0.0089009558 | AA16: =V16/totals!B$4 -> -0.0031843453 | AB16: =AB15+AA16 -> 0.0049287635
A17: 7940 | B17: =VLOOKUP($A17,product_category,2, False) -> Household | C17: 107651269 | D17: 41575 | E17: =month(D17) -> 10 | F17: =text(D17,"MMM") -> Oct | G17: =Day(D17) -> 28 | H17: =year(D17) -> 2013 | I17: 41589 | J17: =DATEDIF(D17,I17,"D") -> 14 | K17: M | L17: HRV | M17: =VLOOKUP(L17,countries, 2,false) -> Croatia | N17: =VLOOKUP(L17,countries, 4,false) -> Europe | O17: =VLOOKUP(L17,countries, 5,false) -> Southern Europe | P17: Online | Q17: 5258 | R17: 668.27 | S17: 502.54 | T17: =MULTIPLY(Q17,R17) -> 3513763.7 | U17: =MULTIPLY(Q18,S18) -> 1438765.5 | V17: =MINUS(T17,U17) -> 2074998.2 | W17: =Q17/totals!B$2 -> 0.0007995105 | X17: =W17+X16 -> 0.011586972 | Y17: =T17/totals!B$5 -> 0.002064334 | Z17: =Z16+Y17 -> 0.01096529 | AA17: =V17/totals!B$4 -> 0.0041374963 | AB17: =AB16+AA17 -> 0.0090662598
A18: 7331 | B18: =VLOOKUP($A18,product_category,2, False) -> Baby Food | C18: 108407437 | D18: 42054 | E18: =month(D18) -> 2 | F18: =text(D18,"MMM") -> Feb | G18: =Day(D18) -> 19 | H18: =year(D18) -> 2015 | I18: 42090 | J18: =DATEDIF(D18,I18,"D") -> 36 | K18: C | L18: ROU | M18: =VLOOKUP(L18,countries, 2,false) -> Romania | N18: =VLOOKUP(L18,countries, 4,false) -> Europe | O18: =VLOOKUP(L18,countries, 5,false) -> Eastern Europe | P18: Offline | Q18: 9025 | R18: 255.28 | S18: 159.42 | T18: =MULTIPLY(Q18,R18) -> 2303902 | U18: =MULTIPLY(Q19,S19) -> 175902.72 | V18: =MINUS(T18,U18) -> 2127999.3 | W18: =Q18/totals!B$2 -> 0.0013723055 | X18: =W18+X17 -> 0.012959278 | Y18: =T18/totals!B$5 -> 0.001353541 | Z18: =Z17+Y18 -> 0.012318831 | AA18: =V18/totals!B$4 -> 0.0042431792 | AB18: =AB17+AA18 -> 0.013309439
A19: 2455 | B19: =VLOOKUP($A19,product_category,2, False) -> Clothes | C19: 109914195 | D19: 40980 | E19: =month(D19) -> 3 | F19: =text(D19,"MMM") -> Mar | G19: =Day(D19) -> 12 | H19: =year(D19) -> 2012 | I19: 41015 | J19: =DATEDIF(D19,I19,"D") -> 35 | K19: M | L19: POL | M19: =VLOOKUP(L19,countries, 2,false) -> Poland | N19: =VLOOKUP(L19,countries, 4,false) -> Europe | O19: =VLOOKUP(L19,countries, 5,false) -> Eastern Europe | P19: Offline | Q19: 4908 | R19: 109.28 | S19: 35.84 | T19: =MULTIPLY(Q19,R19) -> 536346.24 | U19: =MULTIPLY(Q20,S20) -> 777331.92 | V19: =MINUS(T19,U19) -> -240985.68 | W19: =Q19/totals!B$2 -> 0.0007462909 | X19: =W19+X18 -> 0.013705568 | Y19: =T19/totals!B$5 -> 0.00031510309 | Z19: =Z18+Y19 -> 0.012633934 | AA19: =V19/totals!B$4 -> -0.00048051963 | AB19: =AB18+AA19 -> 0.012828919
A20: 7331 | B20: =VLOOKUP($A20,product_category,2, False) -> Baby Food | C20: 111063039 | D20: 41055 | E20: =month(D20) -> 5 | F20: =text(D20,"MMM") -> May | G20: =Day(D20) -> 26 | H20: =year(D20) -> 2012 | I20: 41103 | J20: =DATEDIF(D20,I20,"D") -> 48 | K20: L | L20: LUX | M20: =VLOOKUP(L20,countries, 2,false) -> Luxembourg | N20: =VLOOKUP(L20,countries, 4,false) -> Europe | O20: =VLOOKUP(L20,countries, 5,false) -> Western Europe | P20: Online | Q20: 4876 | R20: 255.28 | S20: 159.42 | T20: =MULTIPLY(Q20,R20) -> 1244745.3 | U20: =MULTIPLY(Q21,S21) -> 3319773.1 | V20: =MINUS(T20,U20) -> -2075027.8 | W20: =Q20/totals!B$2 -> 0.00074142511 | X20: =W20+X19 -> 0.014446994 | Y20: =T20/totals!B$5 -> 0.0007312871 | Z20: =Z19+Y20 -> 0.013365221 | AA20: =V20/totals!B$4 -> -0.0041375554 | AB20: =AB19+AA20 -> 0.0086913641
A21: 8875 | B21: =VLOOKUP($A21,product_category,2, False) -> Meat | C21: 111246287 | D21: 42895 | E21: =month(D21) -> 6 | F21: =text(D21,"MMM") -> Jun | G21: =Day(D21) -> 9 | H21: =year(D21) -> 2017 | I21: 42918 | J21: =DATEDIF(D21,I21,"D") -> 23 | K21: M | L21: CYP | M21: =VLOOKUP(L21,countries, 2,false) -> Cyprus | N21: =VLOOKUP(L21,countries, 4,false) -> Asia | O21: =VLOOKUP(L21,countries, 5,false) -> Western Asia | P21: Offline | Q21: 9103 | R21: 421.89 | S21: 364.69 | T21: =MULTIPLY(Q21,R21) -> 3840464.7 | U21: =MULTIPLY(Q22,S22) -> 20863.8 | V21: =MINUS(T21,U21) -> 3819600.9 | W21: =Q21/totals!B$2 -> 0.0013841659 | X21: =W21+X20 -> 0.015831159 | Y21: =T21/totals!B$5 -> 0.0022562707 | Z21: =Z20+Y21 -> 0.015621492 | AA21: =V21/totals!B$4 -> 0.007616192 | AB21: =AB20+AA21 -> 0.016307556
A22: 4594 | B22: =VLOOKUP($A22,product_category,2, False) -> Fruits | C22: 111496055 | D22: 40661 | E22: =month(D22) -> 4 | F22: =text(D22,"MMM") -> Apr | G22: =Day(D22) -> 28 | H22: =year(D22) -> 2011 | I22: 40698 | J22: =DATEDIF(D22,I22,"D") -> 37 | K22: M | L22: BEL | M22: =VLOOKUP(L22,countries, 2,false) -> Belgium | N22: =VLOOKUP(L22,countries, 4,false) -> Europe | O22: =VLOOKUP(L22,countries, 5,false) -> Western Europe | P22: Online | Q22: 3015 | R22: 9.33 | S22: 6.92 | T22: =MULTIPLY(Q22,R22) -> 28129.95 | U22: =MULTIPLY(Q23,S23) -> 77478.12 | V22: =MINUS(T22,U22) -> -49348.17 | W22: =Q22/totals!B$2 -> 0.00045844887 | X22: =W22+X21 -> 0.016289608 | Y22: =T22/totals!B$5 -> 1.6526329e-05 | Z22: =Z21+Y22 -> 0.015638018 | AA22: =V22/totals!B$4 -> -9.8399061e-05 | AB22: =AB21+AA22 -> 0.016209157
A23: 7331 | B23: =VLOOKUP($A23,product_category,2, False) -> Baby Food | C23: 111893022 | D23: 42671 | E23: =month(D23) -> 10 | F23: =text(D23,"MMM") -> Oct | G23: =Day(D23) -> 28 | H23: =year(D23) -> 2016 | I23: 42706 | J23: =DATEDIF(D23,I23,"D") -> 35 | K23: L | L23: SVN | M23: =VLOOKUP(L23,countries, 2,false) -> Slovenia | N23: =VLOOKUP(L23,countries, 4,false) -> Europe | O23: =VLOOKUP(L23,countries, 5,false) -> Southern Europe | P23: Online | Q23: 486 | R23: 255.28 | S23: 159.42 | T23: =MULTIPLY(Q23,R23) -> 124066.08 | U23: =MULTIPLY(Q24,S24) -> 11549.12 | V23: =MINUS(T23,U23) -> 112516.96 | W23: =Q23/totals!B$2 -> 7.3899221e-05 | X23: =W23+X22 -> 0.016363508 | Y23: =T23/totals!B$5 -> 7.2888747e-05 | Z23: =Z22+Y23 -> 0.015710907 | AA23: =V23/totals!B$4 -> 0.0002243561 | AB23: =AB22+AA23 -> 0.016433513
A24: 8681 | B24: =VLOOKUP($A24,product_category,2, False) -> Office Supplies | C24: 112330758 | D24: 42719 | E24: =month(D24) -> 12 | F24: =text(D24,"MMM") -> Dec | G24: =Day(D24) -> 15 | H24: =year(D24) -> 2016 | I24: 42746 | J24: =DATEDIF(D24,I24,"D") -> 27 | K24: C | L24: LTU | M24: =VLOOKUP(L24,countries, 2,false) -> Lithuania | N24: =VLOOKUP(L24,countries, 4,false) -> Europe | O24: =VLOOKUP(L24,countries, 5,false) -> Northern Europe | P24: Offline | Q24: 22 | R24: 651.21 | S24: 524.96 | T24: =MULTIPLY(Q24,R24) -> 14326.62 | U24: =MULTIPLY(Q25,S25) -> 875572.25 | V24: =MINUS(T24,U24) -> -861245.63 | W24: =Q24/totals!B$2 -> 3.3452322e-06 | X24: =W24+X23 -> 0.016366853 | Y24: =T24/totals!B$5 -> 8.4168806e-06 | Z24: =Z23+Y24 -> 0.015719324 | AA24: =V24/totals!B$4 -> -0.001717303 | AB24: =AB23+AA24 -> 0.01471621
A25: 8293 | B25: =VLOOKUP($A25,product_category,2, False) -> Cosmetics | C25: 113524663 | D25: 40480 | E25: =month(D25) -> 10 | F25: =text(D25,"MMM") -> Oct | G25: =Day(D25) -> 29 | H25: =year(D25) -> 2010 | I25: 40521 | J25: =DATEDIF(D25,I25,"D") -> 41 | K25: L | L25: RUS | M25: =VLOOKUP(L25,countries, 2,false) -> Russia | N25: =VLOOKUP(L25,countries, 4,false) -> Europe | O25: =VLOOKUP(L25,countries, 5,false) -> Eastern Europe | P25: Online | Q25: 3325 | R25: 437.2 | S25: 263.33 | T25: =MULTIPLY(Q25,R25) -> 1453690 | U25: =MULTIPLY(Q26,S26) -> 43935.08 | V25: =MINUS(T25,U25) -> 1409754.9 | W25: =Q25/totals!B$2 -> 0.00050558623 | X25: =W25+X24 -> 0.016872439 | Y25: =T25/totals!B$5 -> 0.000854042 | Z25: =Z24+Y25 -> 0.016573366 | AA25: =V25/totals!B$4 -> 0.0028110173 | AB25: =AB24+AA25 -> 0.017527227
A26: 4594 | B26: =VLOOKUP($A26,product_category,2, False) -> Fruits | C26: 114954173 | D26: 40212 | E26: =month(D26) -> 2 | F26: =text(D26,"MMM") -> Feb | G26: =Day(D26) -> 3 | H26: =year(D26) -> 2010 | I26: 40220 | J26: =DATEDIF(D26,I26,"D") -> 8 | K26: C | L26: MLT | M26: =VLOOKUP(L26,countries, 2,false) -> Malta | N26: =VLOOKUP(L26,countries, 4,false) -> Europe | O26: =VLOOKUP(L26,countries, 5,false) -> Southern Europe | P26: Offline | Q26: 6349 | R26: 9.33 | S26: 6.92 | T26: =MULTIPLY(Q26,R26) -> 59236.17 | U26: =MULTIPLY(Q27,S27) -> 3872105 | V26: =MINUS(T26,U26) -> -3812868.8 | W26: =Q26/totals!B$2 -> 0.00096540361 | X26: =W26+X25 -> 0.017837843 | Y26: =T26/totals!B$5 -> 3.4801214e-05 | Z26: =Z25+Y26 -> 0.016608167 | AA26: =V26/totals!B$4 -> -0.0076027684 | AB26: =AB25+AA26 -> 0.009924459
A27: 8681 | B27: =VLOOKUP($A27,product_category,2, False) -> Office Supplies | C27: 115363156 | D27: 42342 | E27: =month(D27) -> 12 | F27: =text(D27,"MMM") -> Dec | G27: =Day(D27) -> 4 | H27: =year(D27) -> 2015 | I27: 42379 | J27: =DATEDIF(D27,I27,"D") -> 37 | K27: H | L27: UKR | M27: =VLOOKUP(L27,countries, 2,false) -> Ukraine | N27: =VLOOKUP(L27,countries, 4,false) -> Europe | O27: =VLOOKUP(L27,countries, 5,false) -> Eastern Europe | P27: Offline | Q27: 7376 | R27: 651.21 | S27: 524.96 | T27: =MULTIPLY(Q27,R27) -> 4803325 | U27: =MULTIPLY(Q28,S28) -> 47145.96 | V27: =MINUS(T27,U27) -> 4756179 | W27: =Q27/totals!B$2 -> 0.0011215651 | X27: =W27+X26 -> 0.018959408 | Y27: =T27/totals!B$5 -> 0.0028219505 | Z27: =Z26+Y27 -> 0.019430117 | AA27: =V27/totals!B$4 -> 0.0094837062 | AB27: =AB26+AA27 -> 0.019408165
A28: 4594 | B28: =VLOOKUP($A28,product_category,2, False) -> Fruits | C28: 117929494 | D28: 42028 | E28: =month(D28) -> 1 | F28: =text(D28,"MMM") -> Jan | G28: =Day(D28) -> 24 | H28: =year(D28) -> 2015 | I28: 42065 | J28: =DATEDIF(D28,I28,"D") -> 37 | K28: H | L28: #N/A | P28: Offline | Q28: 6813 | R28: 9.33 | S28: 6.92 | T28: =MULTIPLY(Q28,R28) -> 63565.29 | U28: =MULTIPLY(Q29,S29) -> 320869.92 | V28: =MINUS(T28,U28) -> -257304.63 | W28: =Q28/totals!B$2 -> 0.0010359576 | X28: =W28+X27 -> 0.019995365 | Y28: =T28/totals!B$5 -> 3.734457e-05 | Z28: =Z27+Y28 -> 0.019467462 | AA28: =V28/totals!B$4 -> -0.00051305923 | AB28: =AB27+AA28 -> 0.018895106
A29: 8969 | B29: =VLOOKUP($A29,product_category,2, False) -> Snacks | C29: 118086564 | D29: 42419 | E29: =month(D29) -> 2 | F29: =text(D29,"MMM") -> Feb | G29: =Day(D29) -> 19 | H29: =year(D29) -> 2016 | I29: 42442 | J29: =DATEDIF(D29,I29,"D") -> 23 | K29: M | L29: NOR | M29: =VLOOKUP(L29,countries, 2,false) -> Norway | N29: =VLOOKUP(L29,countries, 4,false) -> Europe | O29: =VLOOKUP(L29,countries, 5,false) -> Northern Europe | P29: Online | Q29: 3293 | R29: 152.58 | S29: 97.44 | T29: =MULTIPLY(Q29,R29) -> 502445.94 | U29: =MULTIPLY(Q30,S30) -> 346645.6 | V29: =MINUS(T29,U29) -> 155800.34 | W29: =Q29/totals!B$2 -> 0.00050072044 | X29: =W29+X28 -> 0.020496086 | Y29: =T29/totals!B$5 -> 0.00029518669 | Z29: =Z28+Y29 -> 0.019762649 | AA29: =V29/totals!B$4 -> 0.00031066212 | AB29: =AB28+AA29 -> 0.019205768
A30: 2103 | B30: =VLOOKUP($A30,product_category,2, False) -> Cereal | C30: 118659913 | D30: 41853 | E30: =month(D30) -> 8 | F30: =text(D30,"MMM") -> Aug | G30: =Day(D30) -> 2 | H30: =year(D30) -> 2014 | I30: 41868 | J30: =DATEDIF(D30,I30,"D") -> 15 | K30: C | L30: CZE | M30: =VLOOKUP(L30,countries, 2,false) -> Czech Republic | N30: =VLOOKUP(L30,countries, 4,false) -> Europe | O30: =VLOOKUP(L30,countries, 5,false) -> Eastern Europe | P30: Online | Q30: 2960 | R30: 205.7 | S30: 117.11 | T30: =MULTIPLY(Q30,R30) -> 608872 | U30: =MULTIPLY(Q31,S31) -> 196146.72 | V30: =MINUS(T30,U30) -> 412725.28 | W30: =Q30/totals!B$2 -> 0.00045008579 | X30: =W30+X29 -> 0.020946172 | Y30: =T30/totals!B$5 -> 0.00035771193 | Z30: =Z29+Y30 -> 0.020120361 | AA30: =V30/totals!B$4 -> 0.00082296425 | AB30: =AB29+AA30 -> 0.020028732
A31: 8969 | B31: =VLOOKUP($A31,product_category,2, False) -> Snacks | C31: 118859469 | D31: 40696 | E31: =month(D31) -> 6 | F31: =text(D31,"MMM") -> Jun | G31: =Day(D31) -> 2 | H31: =year(D31) -> 2011 | I31: 40725 | J31: =DATEDIF(D31,I31,"D") -> 29 | K31: L | L31: #N/A | P31: Offline | Q31: 2013 | R31: 152.58 | S31: 97.44 | T31: =MULTIPLY(Q31,R31) -> 307143.54 | U31: =MULTIPLY(Q32,S32) -> 29411.73 | V31: =MINUS(T31,U31) -> 277731.81 | W31: =Q31/totals!B$2 -> 0.00030608875 | X31: =W31+X30 -> 0.02125226 | Y31: =T31/totals!B$5 -> 0.00018044664 | Z31: =Z30+Y31 -> 0.020300807 | AA31: =V31/totals!B$4 -> 0.00055379053 | AB31: =AB30+AA31 -> 0.020582523
A32: 3127 | B32: =VLOOKUP($A32,product_category,2, False) -> Personal Care | C32: 119935786 | D32: 42018 | E32: =month(D32) -> 1 | F32: =text(D32,"MMM") -> Jan | G32: =Day(D32) -> 14 | H32: =year(D32) -> 2015 | I32: 42031 | J32: =DATEDIF(D32,I32,"D") -> 13 | K32: L | L32: ROU | M32: =VLOOKUP(L32,countries, 2,false) -> Romania | N32: =VLOOKUP(L32,countries, 4,false) -> Europe | O32: =VLOOKUP(L32,countries, 5,false) -> Eastern Europe | P32: Offline | Q32: 519 | R32: 81.73 | S32: 56.67 | T32: =MULTIPLY(Q32,R32) -> 42417.87 | U32: =MULTIPLY(Q33,S33) -> 213702.57 | V32: =MINUS(T32,U32) -> -171284.7 | W32: =Q32/totals!B$2 -> 7.8917069e-05 | X32: =W32+X31 -> 0.021331177 | Y32: =T32/totals!B$5 -> 2.4920473e-05 | Z32: =Z31+Y32 -> 0.020325728 | AA32: =V32/totals!B$4 -> -0.00034153756 | AB32: =AB31+AA32 -> 0.020240985
A33: 3127 | B33: =VLOOKUP($A33,product_category,2, False) -> Personal Care | C33: 120419871 | D33: 42137 | E33: =month(D33) -> 5 | F33: =text(D33,"MMM") -> May | G33: =Day(D33) -> 13 | H33: =year(D33) -> 2015 | I33: 42181 | J33: =DATEDIF(D33,I33,"D") -> 44 | K33: H | L33: LTU | M33: =VLOOKUP(L33,countries, 2,false) -> Lithuania | N33: =VLOOKUP(L33,countries, 4,false) -> Europe | O33: =VLOOKUP(L33,countries, 5,false) -> Northern Europe | P33: Online | Q33: 3771 | R33: 81.73 | S33: 56.67 | T33: =MULTIPLY(Q33,R33) -> 308203.83 | U33: =MULTIPLY(Q34,S34) -> 61352.72 | V33: =MINUS(T33,U33) -> 246851.11 | W33: =Q33/totals!B$2 -> 0.00057340321 | X33: =W33+X32 -> 0.021904581 | Y33: =T33/totals!B$5 -> 0.00018106956 | Z33: =Z32+Y33 -> 0.020506797 | AA33: =V33/totals!B$4 -> 0.00049221516 | AB33: =AB32+AA33 -> 0.0207332
A34: 4594 | B34: =VLOOKUP($A34,product_category,2, False) -> Fruits | C34: 120977771 | D34: 40625 | E34: =month(D34) -> 3 | F34: =text(D34,"MMM") -> Mar | G34: =Day(D34) -> 23 | H34: =year(D34) -> 2011 | I34: 40665 | J34: =DATEDIF(D34,I34,"D") -> 40 | K34: M | L34: ARM | M34: =VLOOKUP(L34,countries, 2,false) -> Armenia | N34: =VLOOKUP(L34,countries, 4,false) -> Asia | O34: =VLOOKUP(L34,countries, 5,false) -> Western Asia | P34: Online | Q34: 8866 | R34: 9.33 | S34: 6.92 | T34: =MULTIPLY(Q34,R34) -> 82719.78 | U34: =MULTIPLY(Q35,S35) -> 56155.8 | V34: =MINUS(T34,U34) -> 26563.98 | W34: =Q34/totals!B$2 -> 0.0013481286 | X34: =W34+X33 -> 0.023252709 | Y34: =T34/totals!B$5 -> 4.8597821e-05 | Z34: =Z33+Y34 -> 0.020555395 | AA34: =V34/totals!B$4 -> 5.2967935e-05 | AB34: =AB33+AA34 -> 0.020786168
A35: 4594 | B35: =VLOOKUP($A35,product_category,2, False) -> Fruits | C35: 121380746 | D35: 42695 | E35: =month(D35) -> 11 | F35: =text(D35,"MMM") -> Nov | G35: =Day(D35) -> 21 | H35: =year(D35) -> 2016 | I35: 42722 | J35: =DATEDIF(D35,I35,"D") -> 27 | K35: C | L35: MLT | M35: =VLOOKUP(L35,countries, 2,false) -> Malta | N35: =VLOOKUP(L35,countries, 4,false) -> Europe | O35: =VLOOKUP(L35,countries, 5,false) -> Southern Europe | P35: Online | Q35: 8115 | R35: 9.33 | S35: 6.92 | T35: =MULTIPLY(Q35,R35) -> 75712.95 | U35: =MULTIPLY(Q36,S36) -> 166643.18 | V35: =MINUS(T35,U35) -> -90930.23 | W35: =Q35/totals!B$2 -> 0.0012339345 | X35: =W35+X34 -> 0.024486644 | Y35: =T35/totals!B$5 -> 4.4481312e-05 | Z35: =Z34+Y35 -> 0.020599876 | AA35: =V35/totals!B$4 -> -0.00018131269 | AB35: =AB34+AA35 -> 0.020604856
A36: 1270 | B36: =VLOOKUP($A36,product_category,2, False) -> Beverages | C36: 121945512 | D36: 42833 | E36: =month(D36) -> 4 | F36: =text(D36,"MMM") -> Apr | G36: =Day(D36) -> 8 | H36: =year(D36) -> 2017 | I36: 42837 | J36: =DATEDIF(D36,I36,"D") -> 4 | K36: C | L36: GBR | M36: =VLOOKUP(L36,countries, 2,false) -> United Kingdom | N36: =VLOOKUP(L36,countries, 4,false) -> Europe | O36: =VLOOKUP(L36,countries, 5,false) -> Northern Europe | P36: Online | Q36: 5242 | R36: 47.45 | S36: 31.79 | T36: =MULTIPLY(Q36,R36) -> 248732.9 | U36: =MULTIPLY(Q37,S37) -> 128463.39 | V36: =MINUS(T36,U36) -> 120269.51 | W36: =Q36/totals!B$2 -> 0.00079707761 | X36: =W36+X35 -> 0.025283721 | Y36: =T36/totals!B$5 -> 0.00014613043 | Z36: =Z35+Y36 -> 0.020746007 | AA36: =V36/totals!B$4 -> 0.0002398145 | AB36: =AB35+AA36 -> 0.02084467
A37: 1270 | B37: =VLOOKUP($A37,product_category,2, False) -> Beverages | C37: 122144210 | D37: 42852 | E37: =month(D37) -> 4 | F37: =text(D37,"MMM") -> Apr | G37: =Day(D37) -> 27 | H37: =year(D37) -> 2017 | I37: 42879 | J37: =DATEDIF(D37,I37,"D") -> 27 | K37: C | L37: MNE | M37: =VLOOKUP(L37,countries, 2,false) -> Montenegro | N37: =VLOOKUP(L37,countries, 4,false) -> Europe | O37: =VLOOKUP(L37,countries, 5,false) -> Southern Europe | P37: Offline | Q37: 4041 | R37: 47.45 | S37: 31.79 | T37: =MULTIPLY(Q37,R37) -> 191745.45 | U37: =MULTIPLY(Q38,S38) -> 50959.37 | V37: =MINUS(T37,U37) -> 140786.08 | W37: =Q37/totals!B$2 -> 0.00061445834 | X37: =W37+X36 -> 0.02589818 | Y37: =T37/totals!B$5 -> 0.00011265034 | Z37: =Z36+Y37 -> 0.020858657 | AA37: =V37/totals!B$4 -> 0.00028072405 | AB37: =AB36+AA37 -> 0.021125394
A38: 1270 | B38: =VLOOKUP($A38,product_category,2, False) -> Beverages | C38: 122372519 | D38: 42379 | E38: =month(D38) -> 1 | F38: =text(D38,"MMM") -> Jan | G38: =Day(D38) -> 10 | H38: =year(D38) -> 2016 | I38: 42382 | J38: =DATEDIF(D38,I38,"D") -> 3 | K38: L | L38: PRT | M38: =VLOOKUP(L38,countries, 2,false) -> Portugal | N38: =VLOOKUP(L38,countries, 4,false) -> Europe | O38: =VLOOKUP(L38,countries, 5,false) -> Southern Europe | P38: Offline | Q38: 1603 | R38: 47.45 | S38: 31.79 | T38: =MULTIPLY(Q38,R38) -> 76062.35 | U38: =MULTIPLY(Q39,S39) -> 242208.01 | V38: =MINUS(T38,U38) -> -166145.66 | W38: =Q38/totals!B$2 -> 0.00024374578 | X38: =W38+X37 -> 0.026141925 | Y38: =T38/totals!B$5 -> 4.4686585e-05 | Z38: =Z37+Y38 -> 0.020903344 | AA38: =V38/totals!B$4 -> -0.00033129044 | AB38: =AB37+AA38 -> 0.020794104
A39: 1270 | B39: =VLOOKUP($A39,product_category,2, False) -> Beverages | C39: 122967326 | D39: 42818 | E39: =month(D39) -> 3 | F39: =text(D39,"MMM") -> Mar | G39: =Day(D39) -> 24 | H39: =year(D39) -> 2017 | I39: 42850 | J39: =DATEDIF(D39,I39,"D") -> 32 | K39: H | L39: BLR | M39: =VLOOKUP(L39,countries, 2,false) -> Belarus | N39: =VLOOKUP(L39,countries, 4,false) -> Europe | O39: =VLOOKUP(L39,countries, 5,false) -> Eastern Europe | P39: Online | Q39: 7619 | R39: 47.45 | S39: 31.79 | T39: =MULTIPLY(Q39,R39) -> 361521.55 | U39: =MULTIPLY(Q40,S40) -> 445897.74 | V39: =MINUS(T39,U39) -> -84376.19 | W39: =Q39/totals!B$2 -> 0.0011585147 | X39: =W39+X38 -> 0.02730044 | Y39: =T39/totals!B$5 -> 0.00021239369 | Z39: =Z38+Y39 -> 0.021115737 | AA39: =V39/totals!B$4 -> -0.00016824409 | AB39: =AB38+AA39 -> 0.02062586
A40: 7331 | B40: =VLOOKUP($A40,product_category,2, False) -> Baby Food | C40: 123086202 | D40: 41641 | E40: =month(D40) -> 1 | F40: =text(D40,"MMM") -> Jan | G40: =Day(D40) -> 2 | H40: =year(D40) -> 2014 | I40: 41690 | J40: =DATEDIF(D40,I40,"D") -> 49 | K40: M | L40: EST | M40: =VLOOKUP(L40,countries, 2,false) -> Estonia | N40: =VLOOKUP(L40,countries, 4,false) -> Europe | O40: =VLOOKUP(L40,countries, 5,false) -> Northern Europe | P40: Offline | Q40: 2797 | R40: 255.28 | S40: 159.42 | T40: =MULTIPLY(Q40,R40) -> 714018.16 | U40: =MULTIPLY(Q41,S41) -> 972247.22 | V40: =MINUS(T40,U40) -> -258229.06 | W40: =Q40/totals!B$2 -> 0.00042530066 | X40: =W40+X39 -> 0.027725741 | Y40: =T40/totals!B$5 -> 0.00041948524 | Z40: =Z39+Y40 -> 0.021535223 | AA40: =V40/totals!B$4 -> -0.00051490252 | AB40: =AB39+AA40 -> 0.020110957
...

Sheet ABC analysis
E1: percentile units sold | F1: percentile total revenue | G1: percentile total profit
E2: =B2/sum(B$2:B$13) -> 0.10230889 | F2: =C2/sum(C$2:C$13) -> 0.25044801 | G2: =D2/sum(D$2:D$13) -> 0.62340611
E3: =B3/sum(B$2:B$13) -> 0.1213393 | F3: =C3/sum(C$2:C$13) -> 0.1994182 | G3: =D3/sum(D$2:D$13) -> 0.48221921
E4: =B4/sum(B$2:B$13) -> 0.064639509 | F4: =C4/sum(C$2:C$13) -> 0.16238024 | G4: =D4/sum(D$2:D$13) -> 0.39172304
E5: =B5/sum(B$2:B$13) -> 0.085146078 | F5: =C5/sum(C$2:C$13) -> 0.13503522 | G5: =D5/sum(D$2:D$13) -> -0.099545337
E6: =B6/sum(B$2:B$13) -> 0.14441065 | F6: =C6/sum(C$2:C$13) -> 0.082828536 | G6: =D6/sum(D$2:D$13) -> 0.1018468
E7: =B7/sum(B$2:B$13) -> 0.091114989 | F7: =C7/sum(C$2:C$13) -> 0.052767059 | G7: =D7/sum(D$2:D$13) -> -0.061601213
E8: =B8/sum(B$2:B$13) -> 0.044795071 | F8: =C8/sum(C$2:C$13) -> 0.042986312 | G8: =D8/sum(D$2:D$13) -> 0.05925738
E9: =B9/sum(B$2:B$13) -> 0.15765325 | F9: =C9/sum(C$2:C$13) -> 0.028120454 | G9: =D9/sum(D$2:D$13) -> -0.070835919
E10: =B10/sum(B$2:B$13) -> 0.047137844 | F10: =C10/sum(C$2:C$13) -> 0.019363933 | G10: =D10/sum(D$2:D$13) -> -0.11455335
E11: =B11/sum(B$2:B$13) -> 0.050421232 | F11: =C11/sum(C$2:C$13) -> 0.015490952 | G11: =D11/sum(D$2:D$13) -> -0.089967276
E12: =B12/sum(B$2:B$13) -> 0.010794673 | F12: =C12/sum(C$2:C$13) -> 0.0083469337 | G12: =D12/sum(D$2:D$13) -> -0.1576391
E13: =B13/sum(B$2:B$13) -> 0.080238523 | F13: =C13/sum(C$2:C$13) -> 0.0028141532 | G13: =D13/sum(D$2:D$13) -> -0.064310343

Sheet products
A1: id | B1: item_type
A2: 2103 | B2: Cereal
A3: 7940 | B3: Household
A4: 2455 | B4: Clothes
A5: 1270 | B5: Beverages
A6: 8681 | B6: Office Supplies
A7: 4594 | B7: Fruits
A8: 5988 | B8: Vegetables
A9: 7331 | B9: Baby Food
A10: 8875 | B10: Meat
A11: 8293 | B11: Cosmetics
A12: 8969 | B12: Snacks
A13: 3127 | B13: Personal Care

Sheet totals
A2: total units sold | B2: =sum(events!Q2:Q1331) -> 6576524
A3: total orders | B3: =count(events!C2:C1001) -> 1330
A4: total profit | B4: =sum(events!V2:V1331) -> 5.0151058e+08 | W4: =Q2/B2 -> 0
A5: total revenue | B5: =sum(events!T2:T1331) -> 1702129408
A6: total countries | B6: =countif(countries!B2:B250,"*") -> 249

Sheet performance by channel

Sheet performance by category

Sheet performance by country

Sheet performance by region

Sheet performance by subregion

Sheet time of shipment performance
I1: region | J1: time of shipment | K1: total profit
I2: Asia | J2: 25.5 | K2: 18934359
I3: Europe | J3: 25 | K3: 4.5774499e+08

Sheet performance by year and month

Sheet profit by country
